Workbook

Sheet 사용안내
A1: 프랜차이즈 지역·업종·브랜드 매출 및 운영이익 분석
A4: 목적 | B4: 지역·업종·브랜드별 점포 수 집계, 매출 비교, 입력 비용 기반 예상 운영이익, 계산식 검증, API용 함수 예시를 한 파일에 통합했습니다.
A5: 사용 순서 | B5: 1) 비용_입력 시트의 노란색 입력값 수정 → 2) 운영이익 시트 확인 → 3) 업종_평균매출·브랜드_매출비교·지역_집계 결과 확인
A6: 매출 단위 | B6: 브랜드 매출비교는 월 매출(원/월)과 연 매출(원/년)입니다. 커피 정보공개서의 평균매출액(천원/년)은 월 환산해 비교했습니다.
A7: 누락 처리 | B7: 원자료의 빈칸·“-”는 0이 아니라 미확인으로 유지했습니다. 업종 평균은 실제 매출 수치가 있는 브랜드만 평균에 포함합니다.
A8: 지역 기준 | B8: 치킨·편의점은 현재 공식 매장찾기 서울 구별 집계, 이미용은 서울·경기 연말 점포 수, 커피는 정보공개서 지역별 가맹점 수를 사용합니다. 기준연도가 서로 다를 수 있습니다.
A9: 운영이익 정의 | B9: 월 운영이익 = 월매출 × (1 − 변동비율 합계) − 월 고정비. 세금·감가상각·금융비용·점포권리금 등은 포함하지 않은 관리용 추정치입니다.
A10: 검증 범위 | B10: 검증 시트에서 원자료 합계 대조, 매출 표본 수, 누락 수, 이익 산식 재계산 일치 여부를 확인합니다.
A11: 원자료 | B11: 첨부된 자료.zip 내부 XLSX 파일을 기준으로 작성했으며, 원본 상대경로는 원천_브랜드·원천_지역 시트에 기록했습니다.

Sheet 브랜드_매출비교
A1: 브랜드별 매출·점포·창업비용 통합 원장
A2: 원자료 기준일·출처·누락 사유를 보존한 분석용 통합본입니다. 파란 글씨/노란 배경은 사용자가 수정할 입력값입니다.
A4: 업종 | B4: 브랜드 | C4: 매출 기준연도 | D4: 월평균 매출(원/월) | E4: 연환산 매출(원/년) | F4: 매장 수 | G4: 매장수 기준연도 | H4: 숫자형 창업비용 합계(원) | I4: 비용 집계 기준 | J4: 매출 출처/시트 | K4: 원본 상대경로
A5: 이미용 | B5: AivaHair | C5: 2025 | D5: 28980000 | E5: 347760000 | I5: 원자료에서 숫자형 창업비용 합계 미확인 | J5: 연도별 요약; 원자료 단위 만원/월 | K5: 이미용/AivaHair_2024-2025_SeoulGyeonggi.xlsx
A6: 이미용 | B6: Blueclub | C6: 2025 | D6: 6870000 | E6: 82440000 | I6: 원자료에서 숫자형 창업비용 합계 미확인 | J6: 연도별 요약; 원자료 단위 만원/월 | K6: 이미용/Blueclub_2024-2025_SeoulGyeonggi.xlsx
A7: 이미용 | B7: LeeChulHairKeker | C7: 2024 | D7: 42690000 | E7: 512280000 | I7: 원자료에서 숫자형 창업비용 합계 미확인 | J7: 연도별 요약; 원자료 단위 만원/월 | K7: 이미용/LeeChulHairKeker_2024-2025_SeoulGyeonggi.xlsx
A8: 이미용 | B8: ParkSeungChul | C8: 2024 | D8: 45170000 | E8: 542040000 | I8: 원자료에서 숫자형 창업비용 합계 미확인 | J8: 연도별 요약; 원자료 단위 만원/월 | K8: 이미용/ParkSeungChul_2024-2025_SeoulGyeonggi.xlsx
A9: 이미용 | B9: XEOHair | C9: 2025 | D9: 36580000 | E9: 438960000 | I9: 원자료에서 숫자형 창업비용 합계 미확인 | J9: 연도별 요약; 원자료 단위 만원/월 | K9: 이미용/XEOHair_2024-2025_SeoulGyeonggi.xlsx
A10: 치킨 | B10: BHC | C10: 2025 | D10: 53080000 | E10: 636960000 | F10: 2224 | G10: 2026 | H10: 278640000 | I10: 원자료에 숫자로 표시된 항목만 합산; -/빈칸은 제외 | J10: 마이프차 연도별 정보; 원자료 단위 원/월 | K10: 치킨/BHC_창업정보.xlsx
A11: 치킨 | B11: 교촌치킨 | C11: 2025 | D11: 65640000 | E11: 787680000 | F11: 1362 | G11: 2025 | H11: 469580000 | I11: 원자료에 숫자로 표시된 항목만 합산; -/빈칸은 제외 | J11: 연도별 정보; 원자료 단위 원/월 | K11: 치킨/교촌치킨_창업정보.xlsx
A12: 치킨 | B12: 굽네치킨 | C12: 2024 | D12: 41550000 | E12: 498600000 | F12: 1252 | G12: 2026 | H12: 166540000 | I12: 원자료에 숫자로 표시된 항목만 합산; -/빈칸은 제외 | J12: 연도별 요청항목; 원자료 단위 원/월 | K12: 치킨/굽네치킨_창업정보.xlsx
A13: 치킨 | B13: 비비큐 | C13: 2024 | D13: 42390000 | E13: 508680000 | F13: 2155 | G13: 2026 | H13: 181560000 | I13: 원자료에 숫자로 표시된 항목만 합산; -/빈칸은 제외 | J13: 캡처 연도별 정보; 원자료 단위 원/월 | K13: 치킨/비비큐_창업정보.xlsx
A14: 치킨 | B14: 처갓집양념치킨 | C14: 2025 | D14: 28570000 | E14: 342840000 | F14: 1251 | G14: 2026 | H14: 58100000 | I14: 원자료에 숫자로 표시된 항목만 합산; -/빈칸은 제외 | J14: 매출 및 매장 수; 원자료 단위 원/월 | K14: 치킨/처갓집양념치킨_창업정보.xlsx
A15: 커피 | B15: 메가커피 | F15: 4016 | G15: 2025 | I15: 원자료에서 숫자형 창업비용 합계 미확인 | K15: 커피브랜드/1.메가커피/메가커피 정보공개서 2024년.xlsx
A16: 커피 | B16: 메가커피 | I16: 원자료에서 숫자형 창업비용 합계 미확인 | K16: 커피브랜드/1.메가커피/메가커피 정보공개서 2025.xlsx
A17: 커피 | B17: 컴포즈커피 | F17: 2649 | G17: 2024 | I17: 원자료에서 숫자형 창업비용 합계 미확인 | K17: 커피브랜드/2.컴포즈커피/컴포즈커피 정보공개서 2024년.xlsx
A18: 커피 | B18: 이디야커피 | F18: 2581 | G18: 2024 | I18: 원자료에서 숫자형 창업비용 합계 미확인 | K18: 커피브랜드/3.이디야커피/이디야커피 정보공개서 2024년.xlsx
A19: 커피 | B19: 빽다방 | F19: 1715 | G19: 2024 | I19: 원자료에서 숫자형 창업비용 합계 미확인 | K19: 커피브랜드/4.빽다방/빽다방 정보공개서 2024년.xlsx
A20: 커피 | B20: 투썸플레이스 | F20: 1670 | G20: 2024 | I20: 원자료에서 숫자형 창업비용 합계 미확인 | K20: 커피브랜드/5.투썸플레이스/Twosome_Place 정보공개서 2024년.xlsx
A21: 편의점 | B21: CU | F21: 18468 | G21: 2026 | H21: 48440000 | I21: 원자료에 숫자로 표시된 항목만 합산; -/빈칸은 제외 | K21: 편의점/CU_창업정보.xlsx
A22: 편의점 | B22: GS25 | F22: 18005 | G22: 2025 | H22: 45400000 | I22: 원자료에 숫자로 표시된 항목만 합산; -/빈칸은 제외 | K22: 편의점/GS25_창업정보.xlsx
A23: 편의점 | B23: 세븐일레븐 | C23: 2024 | D23: 42600000 | E23: 511200000 | F23: 7568 | G23: 2026 | H23: 148020000 | I23: 원자료에 숫자로 표시된 항목만 합산; -/빈칸은 제외 | J23: 매출 및 매장 수; 원자료 단위 원/월 | K23: 편의점/세븐일레븐_창업정보.xlsx
A24: 편의점 | B24: 이마트24 | C24: 2024 | D24: 37620000 | E24: 451440000 | F24: 5595 | G24: 2026 | H24: 148400000 | I24: 원자료에 숫자로 표시된 항목만 합산; -/빈칸은 제외 | J24: 매출 및 매장 수; 원자료 단위 원/월 | K24: 편의점/이마트24_창업정보.xlsx

Sheet 업종_평균매출
A1: 업종별 평균 매출 및 표본 검증
A2: 원자료 기준일·출처·누락 사유를 보존한 분석용 통합본입니다. 파란 글씨/노란 배경은 사용자가 수정할 입력값입니다.
A4: 업종 | B4: 매출 입력 브랜드 수 | C4: 매출 미확인 브랜드 수 | D4: 평균 월매출(원/월) | E4: 평균 연매출(원/년) | F4: 최고 월매출 브랜드 | G4: 최저 월매출 브랜드 | H4: 산식/해석
A5: 이미용 | B5: =COUNTIFS(브랜드_매출비교!$A$5:$A$24,A5,브랜드_매출비교!$D$5:$D$24,">0") -> 5 | C5: =COUNTIFS(브랜드_매출비교!$A$5:$A$24,A5,브랜드_매출비교!$D$5:$D$24,"=") -> 0 | D5: =IFERROR(AVERAGEIF(브랜드_매출비교!$A$5:$A$24,A5,브랜드_매출비교!$D$5:$D$24),"") -> 32058000 | E5: =IF(D5="","",D5*12) -> 384696000 | F5: =IFERROR(INDEX(브랜드_매출비교!$B$5:$B$24,MATCH(1,(브랜드_매출비교!$A$5:$A$24=A5)*(브랜드_매출비교!$D$5:$D$24=maxifs(브랜드_매출비교!$D$5:$D$24,브랜드_매출비교!$A$5:$A$24,A5)),0)),"") | G5: =IFERROR(INDEX(브랜드_매출비교!$B$5:$B$24,MATCH(1,(브랜드_매출비교!$A$5:$A$24=A5)*(브랜드_매출비교!$D$5:$D$24=minifs(브랜드_매출비교!$D$5:$D$24,브랜드_매출비교!$A$5:$A$24,A5)),0)),"") | H5: 실제 월매출이 숫자로 입력된 브랜드만 평균. 빈칸은 0이 아님.
A6: 치킨 | B6: =COUNTIFS(브랜드_매출비교!$A$5:$A$24,A6,브랜드_매출비교!$D$5:$D$24,">0") -> 5 | C6: =COUNTIFS(브랜드_매출비교!$A$5:$A$24,A6,브랜드_매출비교!$D$5:$D$24,"=") -> 0 | D6: =IFERROR(AVERAGEIF(브랜드_매출비교!$A$5:$A$24,A6,브랜드_매출비교!$D$5:$D$24),"") -> 46246000 | E6: =IF(D6="","",D6*12) -> 554952000 | F6: =IFERROR(INDEX(브랜드_매출비교!$B$5:$B$24,MATCH(1,(브랜드_매출비교!$A$5:$A$24=A6)*(브랜드_매출비교!$D$5:$D$24=maxifs(브랜드_매출비교!$D$5:$D$24,브랜드_매출비교!$A$5:$A$24,A6)),0)),"") | G6: =IFERROR(INDEX(브랜드_매출비교!$B$5:$B$24,MATCH(1,(브랜드_매출비교!$A$5:$A$24=A6)*(브랜드_매출비교!$D$5:$D$24=minifs(브랜드_매출비교!$D$5:$D$24,브랜드_매출비교!$A$5:$A$24,A6)),0)),"") | H6: 실제 월매출이 숫자로 입력된 브랜드만 평균. 빈칸은 0이 아님.
A7: 커피 | B7: =COUNTIFS(브랜드_매출비교!$A$5:$A$24,A7,브랜드_매출비교!$D$5:$D$24,">0") -> 0 | C7: =COUNTIFS(브랜드_매출비교!$A$5:$A$24,A7,브랜드_매출비교!$D$5:$D$24,"=") -> 6 | D7: =IFERROR(AVERAGEIF(브랜드_매출비교!$A$5:$A$24,A7,브랜드_매출비교!$D$5:$D$24),"") | E7: =IF(D7="","",D7*12) | F7: =IFERROR(INDEX(브랜드_매출비교!$B$5:$B$24,MATCH(1,(브랜드_매출비교!$A$5:$A$24=A7)*(브랜드_매출비교!$D$5:$D$24=maxifs(브랜드_매출비교!$D$5:$D$24,브랜드_매출비교!$A$5:$A$24,A7)),0)),"") | G7: =IFERROR(INDEX(브랜드_매출비교!$B$5:$B$24,MATCH(1,(브랜드_매출비교!$A$5:$A$24=A7)*(브랜드_매출비교!$D$5:$D$24=minifs(브랜드_매출비교!$D$5:$D$24,브랜드_매출비교!$A$5:$A$24,A7)),0)),"") | H7: 실제 월매출이 숫자로 입력된 브랜드만 평균. 빈칸은 0이 아님.
A8: 편의점 | B8: =COUNTIFS(브랜드_매출비교!$A$5:$A$24,A8,브랜드_매출비교!$D$5:$D$24,">0") -> 2 | C8: =COUNTIFS(브랜드_매출비교!$A$5:$A$24,A8,브랜드_매출비교!$D$5:$D$24,"=") -> 2 | D8: =IFERROR(AVERAGEIF(브랜드_매출비교!$A$5:$A$24,A8,브랜드_매출비교!$D$5:$D$24),"") -> 40110000 | E8: =IF(D8="","",D8*12) -> 481320000 | F8: =IFERROR(INDEX(브랜드_매출비교!$B$5:$B$24,MATCH(1,(브랜드_매출비교!$A$5:$A$24=A8)*(브랜드_매출비교!$D$5:$D$24=maxifs(브랜드_매출비교!$D$5:$D$24,브랜드_매출비교!$A$5:$A$24,A8)),0)),"") | G8: =IFERROR(INDEX(브랜드_매출비교!$B$5:$B$24,MATCH(1,(브랜드_매출비교!$A$5:$A$24=A8)*(브랜드_매출비교!$D$5:$D$24=minifs(브랜드_매출비교!$D$5:$D$24,브랜드_매출비교!$A$5:$A$24,A8)),0)),"") | H8: 실제 월매출이 숫자로 입력된 브랜드만 평균. 빈칸은 0이 아님.

Sheet 원천_지역
A1: 원천 지역별 점포·매출 데이터
A2: 원자료 기준일·출처·누락 사유를 보존한 분석용 통합본입니다. 파란 글씨/노란 배경은 사용자가 수정할 입력값입니다.
A4: 업종 | B4: 브랜드 | C4: 지역권역 | D4: 지역 | E4: 기준연도 | F4: 수량/매출 값 | G4: 지표/단위 | H4: 원본 상대경로
A5: 이미용 | B5: AivaHair | C5: 서울 | D5: 서울 | E5: 2024 | F5: 130 | G5: 연말 점포 수 | H5: 이미용/AivaHair_2024-2025_SeoulGyeonggi.xlsx#서울경기 점포수
A6: 이미용 | B6: AivaHair | C6: 경기 | D6: 경기 | E6: 2024 | F6: 110 | G6: 연말 점포 수 | H6: 이미용/AivaHair_2024-2025_SeoulGyeonggi.xlsx#서울경기 점포수
A7: 이미용 | B7: AivaHair | C7: 서울 | D7: 서울 | E7: 2025 | F7: 139 | G7: 연말 점포 수 | H7: 이미용/AivaHair_2024-2025_SeoulGyeonggi.xlsx#서울경기 점포수
A8: 이미용 | B8: AivaHair | C8: 경기 | D8: 경기 | E8: 2025 | F8: 126 | G8: 연말 점포 수 | H8: 이미용/AivaHair_2024-2025_SeoulGyeonggi.xlsx#서울경기 점포수
A9: 이미용 | B9: Blueclub | C9: 서울 | D9: 서울 | E9: 2024 | F9: 116 | G9: 연말 점포 수 | H9: 이미용/Blueclub_2024-2025_SeoulGyeonggi.xlsx#서울경기 점포수
A10: 이미용 | B10: Blueclub | C10: 경기 | D10: 경기 | E10: 2024 | F10: 99 | G10: 연말 점포 수 | H10: 이미용/Blueclub_2024-2025_SeoulGyeonggi.xlsx#서울경기 점포수
A11: 이미용 | B11: Blueclub | C11: 서울 | D11: 서울 | E11: 2025 | F11: 116 | G11: 연말 점포 수 | H11: 이미용/Blueclub_2024-2025_SeoulGyeonggi.xlsx#서울경기 점포수
A12: 이미용 | B12: Blueclub | C12: 경기 | D12: 경기 | E12: 2025 | F12: 101 | G12: 연말 점포 수 | H12: 이미용/Blueclub_2024-2025_SeoulGyeonggi.xlsx#서울경기 점포수
A13: 이미용 | B13: LeeChulHairKeker | C13: 서울 | D13: 서울 | E13: 2024 | F13: 43 | G13: 연말 점포 수 | H13: 이미용/LeeChulHairKeker_2024-2025_SeoulGyeonggi.xlsx#서울경기 점포수
A14: 이미용 | B14: LeeChulHairKeker | C14: 경기 | D14: 경기 | E14: 2024 | F14: 65 | G14: 연말 점포 수 | H14: 이미용/LeeChulHairKeker_2024-2025_SeoulGyeonggi.xlsx#서울경기 점포수
A15: 이미용 | B15: ParkSeungChul | C15: 서울 | D15: 서울 | E15: 2024 | F15: 65 | G15: 연말 점포 수 | H15: 이미용/ParkSeungChul_2024-2025_SeoulGyeonggi.xlsx#서울경기 점포수
A16: 이미용 | B16: ParkSeungChul | C16: 경기 | D16: 경기 | E16: 2024 | F16: 61 | G16: 연말 점포 수 | H16: 이미용/ParkSeungChul_2024-2025_SeoulGyeonggi.xlsx#서울경기 점포수
... A18: 이미용 | B18: XEOHair | C18: 경기 | D18: 경기 | E18: 2025 | F18: 8 | G18: 연말 점포 수 | H18: 이미용/XEOHair_2024-2025_SeoulGyeonggi.xlsx#서울경기 점포수
A19: 치킨 | B19: BHC | C19: 서울 | D19: 강남구 | F19: 17 | G19: 현재 공식 매장찾기/자료 기준 | H19: 치킨/BHC_창업정보.xlsx#서울 구별 점포 수
A20: 치킨 | B20: BHC | C20: 서울 | D20: 강동구 | F20: 12 | G20: 현재 공식 매장찾기/자료 기준 | H20: 치킨/BHC_창업정보.xlsx#서울 구별 점포 수
A21: 치킨 | B21: BHC | C21: 서울 | D21: 강북구 | F21: 9 | G21: 현재 공식 매장찾기/자료 기준 | H21: 치킨/BHC_창업정보.xlsx#서울 구별 점포 수
A22: 치킨 | B22: BHC | C22: 서울 | D22: 강서구 | F22: 14 | G22: 현재 공식 매장찾기/자료 기준 | H22: 치킨/BHC_창업정보.xlsx#서울 구별 점포 수
A23: 치킨 | B23: BHC | C23: 서울 | D23: 관악구 | F23: 14 | G23: 현재 공식 매장찾기/자료 기준 | H23: 치킨/BHC_창업정보.xlsx#서울 구별 점포 수
A24: 치킨 | B24: BHC | C24: 서울 | D24: 광진구 | F24: 9 | G24: 현재 공식 매장찾기/자료 기준 | H24: 치킨/BHC_창업정보.xlsx#서울 구별 점포 수
A25: 치킨 | B25: BHC | C25: 서울 | D25: 구로구 | F25: 14 | G25: 현재 공식 매장찾기/자료 기준 | H25: 치킨/BHC_창업정보.xlsx#서울 구별 점포 수
A26: 치킨 | B26: BHC | C26: 서울 | D26: 금천구 | F26: 6 | G26: 현재 공식 매장찾기/자료 기준 | H26: 치킨/BHC_창업정보.xlsx#서울 구별 점포 수
A27: 치킨 | B27: BHC | C27: 서울 | D27: 노원구 | F27: 12 | G27: 현재 공식 매장찾기/자료 기준 | H27: 치킨/BHC_창업정보.xlsx#서울 구별 점포 수
A28: 치킨 | B28: BHC | C28: 서울 | D28: 도봉구 | F28: 7 | G28: 현재 공식 매장찾기/자료 기준 | H28: 치킨/BHC_창업정보.xlsx#서울 구별 점포 수
A29: 치킨 | B29: BHC | C29: 서울 | D29: 동대문구 | F29: 10 | G29: 현재 공식 매장찾기/자료 기준 | H29: 치킨/BHC_창업정보.xlsx#서울 구별 점포 수
A30: 치킨 | B30: BHC | C30: 서울 | D30: 동작구 | F30: 11 | G30: 현재 공식 매장찾기/자료 기준 | H30: 치킨/BHC_창업정보.xlsx#서울 구별 점포 수
... A148: 치킨 | B148: 처갓집양념치킨 | C148: 서울 | D148: 합계 | F148: 139 | G148: 현재 공식 매장찾기/자료 기준 | H148: 치킨/처갓집양념치킨_창업정보.xlsx#서울 구별 점포 수
A149: 커피 | B149: 메가커피 | C149: 전국 | D149: 전체 | E149: 2025 | F149: 3325 | G149: 가맹점 평균 매출 2025년(천원/년) | H149: 커피브랜드/1.메가커피/메가커피 정보공개서 2024년.xlsx#지역별_평균매출액비교
A150: 커피 | B150: 메가커피 | C150: 시도 | D150: 서울 | E150: 2025 | F150: 796 | G150: 가맹점 평균 매출 2025년(천원/년) | H150: 커피브랜드/1.메가커피/메가커피 정보공개서 2024년.xlsx#지역별_평균매출액비교
A151: 커피 | B151: 메가커피 | C151: 시도 | D151: 부산 | E151: 2025 | F151: 103 | G151: 가맹점 평균 매출 2025년(천원/년) | H151: 커피브랜드/1.메가커피/메가커피 정보공개서 2024년.xlsx#지역별_평균매출액비교
A152: 커피 | B152: 메가커피 | C152: 시도 | D152: 대구 | E152: 2025 | F152: 56 | G152: 가맹점 평균 매출 2025년(천원/년) | H152: 커피브랜드/1.메가커피/메가커피 정보공개서 2024년.xlsx#지역별_평균매출액비교
A153: 커피 | B153: 메가커피 | C153: 시도 | D153: 인천 | E153: 2025 | F153: 294 | G153: 가맹점 평균 매출 2025년(천원/년) | H153: 커피브랜드/1.메가커피/메가커피 정보공개서 2024년.xlsx#지역별_평균매출액비교
A154: 커피 | B154: 메가커피 | C154: 시도 | D154: 광주 | E154: 2025 | F154: 141 | G154: 가맹점 평균 매출 2025년(천원/년) | H154: 커피브랜드/1.메가커피/메가커피 정보공개서 2024년.xlsx#지역별_평균매출액비교
A155: 커피 | B155: 메가커피 | C155: 시도 | D155: 대전 | E155: 2025 | F155: 88 | G155: 가맹점 평균 매출 2025년(천원/년) | H155: 커피브랜드/1.메가커피/메가커피 정보공개서 2024년.xlsx#지역별_평균매출액비교
A156: 커피 | B156: 메가커피 | C156: 시도 | D156: 울산 | E156: 2025 | F156: 15 | G156: 가맹점 평균 매출 2025년(천원/년) | H156: 커피브랜드/1.메가커피/메가커피 정보공개서 2024년.xlsx#지역별_평균매출액비교
A157: 커피 | B157: 메가커피 | C157: 시도 | D157: 세종 | E157: 2025 | F157: 20 | G157: 가맹점 평균 매출 2025년(천원/년) | H157: 커피브랜드/1.메가커피/메가커피 정보공개서 2024년.xlsx#지역별_평균매출액비교
A158: 커피 | B158: 메가커피 | C158: 시도 | D158: 경기 | E158: 2025 | F158: 1109 | G158: 가맹점 평균 매출 2025년(천원/년) | H158: 커피브랜드/1.메가커피/메가커피 정보공개서 2024년.xlsx#지역별_평균매출액비교
A159: 커피 | B159: 메가커피 | C159: 시도 | D159: 강원 | E159: 2025 | F159: 104 | G159: 가맹점 평균 매출 2025년(천원/년) | H159: 커피브랜드/1.메가커피/메가커피 정보공개서 2024년.xlsx#지역별_평균매출액비교
...

Sheet 지역_집계
A1: 지역별 집계 및 비교
A2: 원자료 기준일·출처·누락 사유를 보존한 분석용 통합본입니다. 파란 글씨/노란 배경은 사용자가 수정할 입력값입니다.
A4: 업종 | B4: 지역권역 | C4: 지역 | D4: 브랜드 수 | E4: 점포/매출 관측치 수 | F4: 수량·매출 합계 | G4: 평균 수량·매출 | H4: 해석
A5: 이미용 | B5: 경기 | C5: 경기 | D5: =COUNTIF(원천_지역!$A$5:$A$342,A5) -> 14 | E5: =COUNTIFS(원천_지역!$A$5:$A$342,A5,원천_지역!$C$5:$C$342,B5,원천_지역!$D$5:$D$342,C5) -> 7 | F5: =SUMIFS(원천_지역!$F$5:$F$342,원천_지역!$A$5:$A$342,A5,원천_지역!$C$5:$C$342,B5,원천_지역!$D$5:$D$342,C5) -> 570 | G5: =IFERROR(F5/E5,"") -> 81.428571 | H5: 지역·기준연도가 업종별로 다르므로 원천 시트의 지표/단위를 함께 확인
A6: 이미용 | B6: 서울 | C6: 서울 | D6: =COUNTIF(원천_지역!$A$5:$A$342,A6) -> 14 | E6: =COUNTIFS(원천_지역!$A$5:$A$342,A6,원천_지역!$C$5:$C$342,B6,원천_지역!$D$5:$D$342,C6) -> 7 | F6: =SUMIFS(원천_지역!$F$5:$F$342,원천_지역!$A$5:$A$342,A6,원천_지역!$C$5:$C$342,B6,원천_지역!$D$5:$D$342,C6) -> 645 | G6: =IFERROR(F6/E6,"") -> 92.142857 | H6: 지역·기준연도가 업종별로 다르므로 원천 시트의 지표/단위를 함께 확인
A7: 치킨 | B7: 서울 | C7: 강남구 | D7: =COUNTIF(원천_지역!$A$5:$A$342,A7) -> 130 | E7: =COUNTIFS(원천_지역!$A$5:$A$342,A7,원천_지역!$C$5:$C$342,B7,원천_지역!$D$5:$D$342,C7) -> 5 | F7: =SUMIFS(원천_지역!$F$5:$F$342,원천_지역!$A$5:$A$342,A7,원천_지역!$C$5:$C$342,B7,원천_지역!$D$5:$D$342,C7) -> 74 | G7: =IFERROR(F7/E7,"") -> 14.8 | H7: 지역·기준연도가 업종별로 다르므로 원천 시트의 지표/단위를 함께 확인
A8: 치킨 | B8: 서울 | C8: 강동구 | D8: =COUNTIF(원천_지역!$A$5:$A$342,A8) -> 130 | E8: =COUNTIFS(원천_지역!$A$5:$A$342,A8,원천_지역!$C$5:$C$342,B8,원천_지역!$D$5:$D$342,C8) -> 5 | F8: =SUMIFS(원천_지역!$F$5:$F$342,원천_지역!$A$5:$A$342,A8,원천_지역!$C$5:$C$342,B8,원천_지역!$D$5:$D$342,C8) -> 57 | G8: =IFERROR(F8/E8,"") -> 11.4 | H8: 지역·기준연도가 업종별로 다르므로 원천 시트의 지표/단위를 함께 확인
A9: 치킨 | B9: 서울 | C9: 강북구 | D9: =COUNTIF(원천_지역!$A$5:$A$342,A9) -> 130 | E9: =COUNTIFS(원천_지역!$A$5:$A$342,A9,원천_지역!$C$5:$C$342,B9,원천_지역!$D$5:$D$342,C9) -> 5 | F9: =SUMIFS(원천_지역!$F$5:$F$342,원천_지역!$A$5:$A$342,A9,원천_지역!$C$5:$C$342,B9,원천_지역!$D$5:$D$342,C9) -> 33 | G9: =IFERROR(F9/E9,"") -> 6.6 | H9: 지역·기준연도가 업종별로 다르므로 원천 시트의 지표/단위를 함께 확인
A10: 치킨 | B10: 서울 | C10: 강서구 | D10: =COUNTIF(원천_지역!$A$5:$A$342,A10) -> 130 | E10: =COUNTIFS(원천_지역!$A$5:$A$342,A10,원천_지역!$C$5:$C$342,B10,원천_지역!$D$5:$D$342,C10) -> 5 | F10: =SUMIFS(원천_지역!$F$5:$F$342,원천_지역!$A$5:$A$342,A10,원천_지역!$C$5:$C$342,B10,원천_지역!$D$5:$D$342,C10) -> 61 | G10: =IFERROR(F10/E10,"") -> 12.2 | H10: 지역·기준연도가 업종별로 다르므로 원천 시트의 지표/단위를 함께 확인
A11: 치킨 | B11: 서울 | C11: 관악구 | D11: =COUNTIF(원천_지역!$A$5:$A$342,A11) -> 130 | E11: =COUNTIFS(원천_지역!$A$5:$A$342,A11,원천_지역!$C$5:$C$342,B11,원천_지역!$D$5:$D$342,C11) -> 5 | F11: =SUMIFS(원천_지역!$F$5:$F$342,원천_지역!$A$5:$A$342,A11,원천_지역!$C$5:$C$342,B11,원천_지역!$D$5:$D$342,C11) -> 54 | G11: =IFERROR(F11/E11,"") -> 10.8 | H11: 지역·기준연도가 업종별로 다르므로 원천 시트의 지표/단위를 함께 확인
A12: 치킨 | B12: 서울 | C12: 광진구 | D12: =COUNTIF(원천_지역!$A$5:$A$342,A12) -> 130 | E12: =COUNTIFS(원천_지역!$A$5:$A$342,A12,원천_지역!$C$5:$C$342,B12,원천_지역!$D$5:$D$342,C12) -> 5 | F12: =SUMIFS(원천_지역!$F$5:$F$342,원천_지역!$A$5:$A$342,A12,원천_지역!$C$5:$C$342,B12,원천_지역!$D$5:$D$342,C12) -> 41 | G12: =IFERROR(F12/E12,"") -> 8.2 | H12: 지역·기준연도가 업종별로 다르므로 원천 시트의 지표/단위를 함께 확인
A13: 치킨 | B13: 서울 | C13: 구로구 | D13: =COUNTIF(원천_지역!$A$5:$A$342,A13) -> 130 | E13: =COUNTIFS(원천_지역!$A$5:$A$342,A13,원천_지역!$C$5:$C$342,B13,원천_지역!$D$5:$D$342,C13) -> 5 | F13: =SUMIFS(원천_지역!$F$5:$F$342,원천_지역!$A$5:$A$342,A13,원천_지역!$C$5:$C$342,B13,원천_지역!$D$5:$D$342,C13) -> 50 | G13: =IFERROR(F13/E13,"") -> 10 | H13: 지역·기준연도가 업종별로 다르므로 원천 시트의 지표/단위를 함께 확인
A14: 치킨 | B14: 서울 | C14: 금천구 | D14: =COUNTIF(원천_지역!$A$5:$A$342,A14) -> 130 | E14: =COUNTIFS(원천_지역!$A$5:$A$342,A14,원천_지역!$C$5:$C$342,B14,원천_지역!$D$5:$D$342,C14) -> 5 | F14: =SUMIFS(원천_지역!$F$5:$F$342,원천_지역!$A$5:$A$342,A14,원천_지역!$C$5:$C$342,B14,원천_지역!$D$5:$D$342,C14) -> 30 | G14: =IFERROR(F14/E14,"") -> 6 | H14: 지역·기준연도가 업종별로 다르므로 원천 시트의 지표/단위를 함께 확인
A15: 치킨 | B15: 서울 | C15: 노원구 | D15: =COUNTIF(원천_지역!$A$5:$A$342,A15) -> 130 | E15: =COUNTIFS(원천_지역!$A$5:$A$342,A15,원천_지역!$C$5:$C$342,B15,원천_지역!$D$5:$D$342,C15) -> 5 | F15: =SUMIFS(원천_지역!$F$5:$F$342,원천_지역!$A$5:$A$342,A15,원천_지역!$C$5:$C$342,B15,원천_지역!$D$5:$D$342,C15) -> 49 | G15: =IFERROR(F15/E15,"") -> 9.8 | H15: 지역·기준연도가 업종별로 다르므로 원천 시트의 지표/단위를 함께 확인
A16: 치킨 | B16: 서울 | C16: 도봉구 | D16: =COUNTIF(원천_지역!$A$5:$A$342,A16) -> 130 | E16: =COUNTIFS(원천_지역!$A$5:$A$342,A16,원천_지역!$C$5:$C$342,B16,원천_지역!$D$5:$D$342,C16) -> 5 | F16: =SUMIFS(원천_지역!$F$5:$F$342,원천_지역!$A$5:$A$342,A16,원천_지역!$C$5:$C$342,B16,원천_지역!$D$5:$D$342,C16) -> 36 | G16: =IFERROR(F16/E16,"") -> 7.2 | H16: 지역·기준연도가 업종별로 다르므로 원천 시트의 지표/단위를 함께 확인
... A76: 편의점 | B76: 서울 | C76: 합계 | D76: =COUNTIF(원천_지역!$A$5:$A$342,A76) -> 104 | E76: =COUNTIFS(원천_지역!$A$5:$A$342,A76,원천_지역!$C$5:$C$342,B76,원천_지역!$D$5:$D$342,C76) -> 4 | F76: =SUMIFS(원천_지역!$F$5:$F$342,원천_지역!$A$5:$A$342,A76,원천_지역!$C$5:$C$342,B76,원천_지역!$D$5:$D$342,C76) -> 8811 | G76: =IFERROR(F76/E76,"") -> 2202.75 | H76: 지역·기준연도가 업종별로 다르므로 원천 시트의 지표/단위를 함께 확인

Sheet 비용_입력
A1: 운영이익 계산용 비용 입력값
A2: 원자료 기준일·출처·누락 사유를 보존한 분석용 통합본입니다. 파란 글씨/노란 배경은 사용자가 수정할 입력값입니다.
A4: 입력값 | B4: 값 | C4: 단위 | D4: 설명 | E4: 기본값의 성격 | F4: 적용식
A5: 상품/재료 등 변동비율 | B5: 0.35 | C5: 매출 대비 % | D5: 사용자 입력. 업종·브랜드별 실제 원가율로 수정 | E5: 예시 가정 | F5: 월매출×변동비율
A6: 인건비율 | B6: 0.25 | C6: 매출 대비 % | D6: 사용자 입력. 급여·4대보험 등 | E6: 예시 가정 | F6: 월매출×인건비율
A7: 임차료(월) | B7: 3000000 | C7: 원/월 | D7: 사용자 입력. 보증금·권리금 제외 | E7: 예시 가정 | F7: 입력 고정비
A8: 공과금·통신·기타(월) | B8: 1000000 | C8: 원/월 | D8: 사용자 입력 | E8: 예시 가정 | F8: 입력 고정비
A9: 로열티·광고분담률 | B9: 0 | C9: 매출 대비 % | D9: 사용자 입력. 정보공개서 확인 시 수정 | E9: 예시 가정 | F9: 월매출×로열티율
A12: 주의 | B12: 노란색 값을 수정하면 운영이익 시트의 모든 브랜드 결과가 자동으로 바뀝니다. 예시 가정은 원자료 수치가 아닙니다.

Sheet 운영이익
A1: 브랜드별 예상 운영이익
A2: 원자료 기준일·출처·누락 사유를 보존한 분석용 통합본입니다. 파란 글씨/노란 배경은 사용자가 수정할 입력값입니다.
A4: 업종 | B4: 브랜드 | C4: 월매출(원) | D4: 변동비(원) | E4: 인건비(원) | F4: 로열티/광고(원) | G4: 월 고정비(원) | H4: 예상 월 운영이익(원) | I4: 예상 연 운영이익(원) | J4: 운영이익률 | K4: 매출 미확인 여부 | L4: 산식 | M4: 행별 산식 검증
A5: =브랜드_매출비교!A5 -> 이미용 | B5: =브랜드_매출비교!B5 -> AivaHair | C5: =브랜드_매출비교!D5 -> 28980000 | D5: =IF(C5="","",C5*비용_입력!$B$5) -> 10143000 | E5: =IF(C5="","",C5*비용_입력!$B$6) -> 7245000 | F5: =IF(C5="","",C5*비용_입력!$B$9) -> 0 | G5: =IF(C5="","",비용_입력!$B$7+비용_입력!$B$8) -> 4000000 | H5: =IF(C5="","",C5-SUM(D5:G5)) -> 7592000 | I5: =IF(H5="","",H5*12) -> 91104000 | J5: =IFERROR(H5/C5,"") -> 0.26197378 | K5: =IF(C5="","미확인","확인") -> 확인 | L5: 매출−변동비−인건비−로열티/광고−고정비 | M5: =IF(K5="미확인","미확인",IF(ABS(H5-(C5-D5-E5-F5-G5))<0.01,"일치","오류")) -> 일치
A6: =브랜드_매출비교!A6 -> 이미용 | B6: =브랜드_매출비교!B6 -> Blueclub | C6: =브랜드_매출비교!D6 -> 6870000 | D6: =IF(C6="","",C6*비용_입력!$B$5) -> 2404500 | E6: =IF(C6="","",C6*비용_입력!$B$6) -> 1717500 | F6: =IF(C6="","",C6*비용_입력!$B$9) -> 0 | G6: =IF(C6="","",비용_입력!$B$7+비용_입력!$B$8) -> 4000000 | H6: =IF(C6="","",C6-SUM(D6:G6)) -> -1252000 | I6: =IF(H6="","",H6*12) -> -15024000 | J6: =IFERROR(H6/C6,"") -> -0.18224163 | K6: =IF(C6="","미확인","확인") -> 확인 | L6: 매출−변동비−인건비−로열티/광고−고정비 | M6: =IF(K6="미확인","미확인",IF(ABS(H6-(C6-D6-E6-F6-G6))<0.01,"일치","오류")) -> 일치
A7: =브랜드_매출비교!A7 -> 이미용 | B7: =브랜드_매출비교!B7 -> LeeChulHairKeker | C7: =브랜드_매출비교!D7 -> 42690000 | D7: =IF(C7="","",C7*비용_입력!$B$5) -> 14941500 | E7: =IF(C7="","",C7*비용_입력!$B$6) -> 10672500 | F7: =IF(C7="","",C7*비용_입력!$B$9) -> 0 | G7: =IF(C7="","",비용_입력!$B$7+비용_입력!$B$8) -> 4000000 | H7: =IF(C7="","",C7-SUM(D7:G7)) -> 13076000 | I7: =IF(H7="","",H7*12) -> 156912000 | J7: =IFERROR(H7/C7,"") -> 0.30630124 | K7: =IF(C7="","미확인","확인") -> 확인 | L7: 매출−변동비−인건비−로열티/광고−고정비 | M7: =IF(K7="미확인","미확인",IF(ABS(H7-(C7-D7-E7-F7-G7))<0.01,"일치","오류")) -> 일치
A8: =브랜드_매출비교!A8 -> 이미용 | B8: =브랜드_매출비교!B8 -> ParkSeungChul | C8: =브랜드_매출비교!D8 -> 45170000 | D8: =IF(C8="","",C8*비용_입력!$B$5) -> 15809500 | E8: =IF(C8="","",C8*비용_입력!$B$6) -> 11292500 | F8: =IF(C8="","",C8*비용_입력!$B$9) -> 0 | G8: =IF(C8="","",비용_입력!$B$7+비용_입력!$B$8) -> 4000000 | H8: =IF(C8="","",C8-SUM(D8:G8)) -> 14068000 | I8: =IF(H8="","",H8*12) -> 168816000 | J8: =IFERROR(H8/C8,"") -> 0.31144565 | K8: =IF(C8="","미확인","확인") -> 확인 | L8: 매출−변동비−인건비−로열티/광고−고정비 | M8: =IF(K8="미확인","미확인",IF(ABS(H8-(C8-D8-E8-F8-G8))<0.01,"일치","오류")) -> 일치
A9: =브랜드_매출비교!A9 -> 이미용 | B9: =브랜드_매출비교!B9 -> XEOHair | C9: =브랜드_매출비교!D9 -> 36580000 | D9: =IF(C9="","",C9*비용_입력!$B$5) -> 12803000 | E9: =IF(C9="","",C9*비용_입력!$B$6) -> 9145000 | F9: =IF(C9="","",C9*비용_입력!$B$9) -> 0 | G9: =IF(C9="","",비용_입력!$B$7+비용_입력!$B$8) -> 4000000 | H9: =IF(C9="","",C9-SUM(D9:G9)) -> 10632000 | I9: =IF(H9="","",H9*12) -> 127584000 | J9: =IFERROR(H9/C9,"") -> 0.29065063 | K9: =IF(C9="","미확인","확인") -> 확인 | L9: 매출−변동비−인건비−로열티/광고−고정비 | M9: =IF(K9="미확인","미확인",IF(ABS(H9-(C9-D9-E9-F9-G9))<0.01,"일치","오류")) -> 일치
A10: =브랜드_매출비교!A10 -> 치킨 | B10: =브랜드_매출비교!B10 -> BHC | C10: =브랜드_매출비교!D10 -> 53080000 | D10: =IF(C10="","",C10*비용_입력!$B$5) -> 18578000 | E10: =IF(C10="","",C10*비용_입력!$B$6) -> 13270000 | F10: =IF(C10="","",C10*비용_입력!$B$9) -> 0 | G10: =IF(C10="","",비용_입력!$B$7+비용_입력!$B$8) -> 4000000 | H10: =IF(C10="","",C10-SUM(D10:G10)) -> 17232000 | I10: =IF(H10="","",H10*12) -> 206784000 | J10: =IFERROR(H10/C10,"") -> 0.32464205 | K10: =IF(C10="","미확인","확인") -> 확인 | L10: 매출−변동비−인건비−로열티/광고−고정비 | M10: =IF(K10="미확인","미확인",IF(ABS(H10-(C10-D10-E10-F10-G10))<0.01,"일치","오류")) -> 일치
A11: =브랜드_매출비교!A11 -> 치킨 | B11: =브랜드_매출비교!B11 -> 교촌치킨 | C11: =브랜드_매출비교!D11 -> 65640000 | D11: =IF(C11="","",C11*비용_입력!$B$5) -> 22974000 | E11: =IF(C11="","",C11*비용_입력!$B$6) -> 16410000 | F11: =IF(C11="","",C11*비용_입력!$B$9) -> 0 | G11: =IF(C11="","",비용_입력!$B$7+비용_입력!$B$8) -> 4000000 | H11: =IF(C11="","",C11-SUM(D11:G11)) -> 22256000 | I11: =IF(H11="","",H11*12) -> 267072000 | J11: =IFERROR(H11/C11,"") -> 0.33906155 | K11: =IF(C11="","미확인","확인") -> 확인 | L11: 매출−변동비−인건비−로열티/광고−고정비 | M11: =IF(K11="미확인","미확인",IF(ABS(H11-(C11-D11-E11-F11-G11))<0.01,"일치","오류")) -> 일치
A12: =브랜드_매출비교!A12 -> 치킨 | B12: =브랜드_매출비교!B12 -> 굽네치킨 | C12: =브랜드_매출비교!D12 -> 41550000 | D12: =IF(C12="","",C12*비용_입력!$B$5) -> 14542500 | E12: =IF(C12="","",C12*비용_입력!$B$6) -> 10387500 | F12: =IF(C12="","",C12*비용_입력!$B$9) -> 0 | G12: =IF(C12="","",비용_입력!$B$7+비용_입력!$B$8) -> 4000000 | H12: =IF(C12="","",C12-SUM(D12:G12)) -> 12620000 | I12: =IF(H12="","",H12*12) -> 151440000 | J12: =IFERROR(H12/C12,"") -> 0.30373045 | K12: =IF(C12="","미확인","확인") -> 확인 | L12: 매출−변동비−인건비−로열티/광고−고정비 | M12: =IF(K12="미확인","미확인",IF(ABS(H12-(C12-D12-E12-F12-G12))<0.01,"일치","오류")) -> 일치
A13: =브랜드_매출비교!A13 -> 치킨 | B13: =브랜드_매출비교!B13 -> 비비큐 | C13: =브랜드_매출비교!D13 -> 42390000 | D13: =IF(C13="","",C13*비용_입력!$B$5) -> 14836500 | E13: =IF(C13="","",C13*비용_입력!$B$6) -> 10597500 | F13: =IF(C13="","",C13*비용_입력!$B$9) -> 0 | G13: =IF(C13="","",비용_입력!$B$7+비용_입력!$B$8) -> 4000000 | H13: =IF(C13="","",C13-SUM(D13:G13)) -> 12956000 | I13: =IF(H13="","",H13*12) -> 155472000 | J13: =IFERROR(H13/C13,"") -> 0.30563812 | K13: =IF(C13="","미확인","확인") -> 확인 | L13: 매출−변동비−인건비−로열티/광고−고정비 | M13: =IF(K13="미확인","미확인",IF(ABS(H13-(C13-D13-E13-F13-G13))<0.01,"일치","오류")) -> 일치
A14: =브랜드_매출비교!A14 -> 치킨 | B14: =브랜드_매출비교!B14 -> 처갓집양념치킨 | C14: =브랜드_매출비교!D14 -> 28570000 | D14: =IF(C14="","",C14*비용_입력!$B$5) -> 9999500 | E14: =IF(C14="","",C14*비용_입력!$B$6) -> 7142500 | F14: =IF(C14="","",C14*비용_입력!$B$9) -> 0 | G14: =IF(C14="","",비용_입력!$B$7+비용_입력!$B$8) -> 4000000 | H14: =IF(C14="","",C14-SUM(D14:G14)) -> 7428000 | I14: =IF(H14="","",H14*12) -> 89136000 | J14: =IFERROR(H14/C14,"") -> 0.259993 | K14: =IF(C14="","미확인","확인") -> 확인 | L14: 매출−변동비−인건비−로열티/광고−고정비 | M14: =IF(K14="미확인","미확인",IF(ABS(H14-(C14-D14-E14-F14-G14))<0.01,"일치","오류")) -> 일치
A15: =브랜드_매출비교!A15 -> 커피 | B15: =브랜드_매출비교!B15 -> 메가커피 | C15: =브랜드_매출비교!D15 -> 0 | D15: =IF(C15="","",C15*비용_입력!$B$5) | E15: =IF(C15="","",C15*비용_입력!$B$6) | F15: =IF(C15="","",C15*비용_입력!$B$9) | G15: =IF(C15="","",비용_입력!$B$7+비용_입력!$B$8) | H15: =IF(C15="","",C15-SUM(D15:G15)) | I15: =IF(H15="","",H15*12) | J15: =IFERROR(H15/C15,"") | K15: =IF(C15="","미확인","확인") -> 미확인 | L15: 매출−변동비−인건비−로열티/광고−고정비 | M15: =IF(K15="미확인","미확인",IF(ABS(H15-(C15-D15-E15-F15-G15))<0.01,"일치","오류")) -> 미확인
A16: =브랜드_매출비교!A16 -> 커피 | B16: =브랜드_매출비교!B16 -> 메가커피 | C16: =브랜드_매출비교!D16 -> 0 | D16: =IF(C16="","",C16*비용_입력!$B$5) | E16: =IF(C16="","",C16*비용_입력!$B$6) | F16: =IF(C16="","",C16*비용_입력!$B$9) | G16: =IF(C16="","",비용_입력!$B$7+비용_입력!$B$8) | H16: =IF(C16="","",C16-SUM(D16:G16)) | I16: =IF(H16="","",H16*12) | J16: =IFERROR(H16/C16,"") | K16: =IF(C16="","미확인","확인") -> 미확인 | L16: 매출−변동비−인건비−로열티/광고−고정비 | M16: =IF(K16="미확인","미확인",IF(ABS(H16-(C16-D16-E16-F16-G16))<0.01,"일치","오류")) -> 미확인
... A24: =브랜드_매출비교!A24 -> 편의점 | B24: =브랜드_매출비교!B24 -> 이마트24 | C24: =브랜드_매출비교!D24 -> 37620000 | D24: =IF(C24="","",C24*비용_입력!$B$5) -> 13167000 | E24: =IF(C24="","",C24*비용_입력!$B$6) -> 9405000 | F24: =IF(C24="","",C24*비용_입력!$B$9) -> 0 | G24: =IF(C24="","",비용_입력!$B$7+비용_입력!$B$8) -> 4000000 | H24: =IF(C24="","",C24-SUM(D24:G24)) -> 11048000 | I24: =IF(H24="","",H24*12) -> 132576000 | J24: =IFERROR(H24/C24,"") -> 0.29367358 | K24: =IF(C24="","미확인","확인") -> 확인 | L24: 매출−변동비−인건비−로열티/광고−고정비 | M24: =IF(K24="미확인","미확인",IF(ABS(H24-(C24-D24-E24-F24-G24))<0.01,"일치","오류")) -> 일치

Sheet 검증
A1: 분석 결과 검증 및 제한사항
A2: 원자료 기준일·출처·누락 사유를 보존한 분석용 통합본입니다. 파란 글씨/노란 배경은 사용자가 수정할 입력값입니다.
A4: 검증 항목 | B4: 검증 결과 | C4: 기준/계산식 | D4: 상태 | E4: 확인 포인트 | F4: 원자료 한계 | G4: 비고
A5: 브랜드 원장 행 수 | B5: =COUNTA(브랜드_매출비교!$B$5:$B$24) -> 20 | C5: 통합 브랜드 수와 원자료 파일 수 비교 | D5: 확인 | E5: 브랜드별 중복 여부 | F5: 브랜드별 기준연도·자료 출처가 다름
A6: 매출 숫자 표본 수 | B6: =COUNT(브랜드_매출비교!$D$5:$D$24) -> 12 | C6: 월매출 숫자형 셀 개수 | D6: 확인 | E6: 업종 평균 표본 수와 일치해야 함 | F6: 교촌·편의점 일부 등 월매출 미확인
A7: 매출 미확인 수 | B7: =COUNTBLANK(브랜드_매출비교!$D$5:$D$24) -> 8 | C7: 빈칸을 0으로 처리하지 않음 | D7: 확인 | E7: 누락값은 평균에서 제외 | F7: 원자료에서 숫자 미제공
A8: 운영이익 산식 일치 | B8: =COUNTIF(운영이익!$M$5:$M$24,"일치") -> 12 | C8: 각 행의 H열과 C−D−E−F−G 재계산 결과가 일치하는 행 수 | D8: 확인 | E8: 운영이익 시트 M열에 오류가 없어야 함 | F8: 비용 가정은 사용자 입력값 | G8: 미확인 매출 행은 별도 제외
A9: 지역 원천 행 수 | B9: =COUNTA(원천_지역!$B$5:$B$342) -> 338 | C9: 지역 원장에 실제 관측치가 있는지 | D9: 확인 | E9: 지역 집계와 원천 행 수 대조 | F9: 지역 기준·수집시점이 업종별 상이
A12: 주요 제한사항
A13: • | B13: 매출 비교는 원자료가 제공한 대표 평균값을 사용하며, 동일한 VAT 포함 여부·조사기간·평수 기준으로 완전히 통일되지 않을 수 있습니다.
A14: • | B14: 서울 구별 매장 수는 대부분 현재 공식 매장찾기 목록이며 2024/2025년 말 통계가 아닐 수 있습니다.
A15: • | B15: 창업비용 합계는 숫자로 표시된 항목만 합산했고, 원자료의 “-”·빈칸은 미확인으로 제외했습니다.
A16: • | B16: 운영이익은 사용자가 입력한 비용 가정을 적용한 예상치이며 실제 손익계산서·세무 신고용 수치가 아닙니다.

Sheet API_함수
A1: API에 사용할 분석 함수 2종
A2: 원자료 기준일·출처·누락 사유를 보존한 분석용 통합본입니다. 파란 글씨/노란 배경은 사용자가 수정할 입력값입니다.
A4: 함수명 | B4: 목적 | C4: Python 예시 구현 | D4: 입력 예시 | E4: 출력 예시
A5: aggregate_by_dimension | B5: 업종·브랜드·지역 차원별 집계 | C5: def aggregate_by_dimension(rows, dimensions): """rows: [{industry, brand, region, revenue_monthly, stores}]""" out = {} for row in rows: key = tuple(row.get(d) for d in dimensions) bucket = out.setdefault(key, {"count": 0, "revenue_sum": 0, "stores_sum": 0}) bucket["count"] += 1 bucket["revenue_sum"] += row.get("revenue_monthly") or 0 bucket["stores_sum"] += row.get("stores") or 0 return [{**dict(zip(dimensions, key)), **value} for key, value in out.items()] | D5: rows=[{"industry":"치킨","brand":"BBQ","region":"강남구","revenue_monthly":42390000,"stores":25}] aggregate_by_dimension(rows,["industry","region"]) | E5: [{"industry":"치킨","region":"강남구","count":1,"revenue_sum":42390000,"stores_sum":25}]
A6: estimate_operating_profit | B6: 입력 비용으로 월·연 운영이익 계산 | C6: def estimate_operating_profit(revenue_monthly, variable_rate=0.35, labor_rate=0.25, royalty_rate=0.0, fixed_cost=4000000): """누락 매출은 None으로 받아 None 반환; 세금·감가상각 제외""" if revenue_monthly is None: return {"monthly_profit": None, "annual_profit": None, "margin": None} monthly_profit = revenue_monthly * (1-variable_rate-labor_rate-royalty_rate) - fixed_cost return {"monthly_profit": monthly_profit, "annual_profit": monthly_profit * 12, "margin": monthly_profit / revenue_monthly if revenue_monthly else None} | D6: estimate_operating_profit(42390000,0.35,0.25,0.0,4000000) | E6: {"monthly_profit":12917000,"annual_profit":155004000,"margin":0.3046}

Sheet 원천_브랜드
A1: 표준화된 브랜드 원천 데이터 및 출처
A2: 원자료 기준일·출처·누락 사유를 보존한 분석용 통합본입니다. 파란 글씨/노란 배경은 사용자가 수정할 입력값입니다.
A4: 업종 | B4: 브랜드 | C4: 매출 기준연도 | D4: 월평균 매출(원/월) | E4: 연환산 매출(원/년) | F4: 매장 수 | G4: 매장수 기준연도 | H4: 숫자형 창업비용 합계(원) | I4: 비용 집계 기준 | J4: 매출 출처/시트 | K4: 원본 상대경로
A5: 이미용 | B5: AivaHair | C5: 2025 | D5: 28980000 | E5: 347760000 | I5: 원자료에서 숫자형 창업비용 합계 미확인 | J5: 연도별 요약; 원자료 단위 만원/월 | K5: 이미용/AivaHair_2024-2025_SeoulGyeonggi.xlsx
A6: 이미용 | B6: Blueclub | C6: 2025 | D6: 6870000 | E6: 82440000 | I6: 원자료에서 숫자형 창업비용 합계 미확인 | J6: 연도별 요약; 원자료 단위 만원/월 | K6: 이미용/Blueclub_2024-2025_SeoulGyeonggi.xlsx
A7: 이미용 | B7: LeeChulHairKeker | C7: 2024 | D7: 42690000 | E7: 512280000 | I7: 원자료에서 숫자형 창업비용 합계 미확인 | J7: 연도별 요약; 원자료 단위 만원/월 | K7: 이미용/LeeChulHairKeker_2024-2025_SeoulGyeonggi.xlsx
A8: 이미용 | B8: ParkSeungChul | C8: 2024 | D8: 45170000 | E8: 542040000 | I8: 원자료에서 숫자형 창업비용 합계 미확인 | J8: 연도별 요약; 원자료 단위 만원/월 | K8: 이미용/ParkSeungChul_2024-2025_SeoulGyeonggi.xlsx
A9: 이미용 | B9: XEOHair | C9: 2025 | D9: 36580000 | E9: 438960000 | I9: 원자료에서 숫자형 창업비용 합계 미확인 | J9: 연도별 요약; 원자료 단위 만원/월 | K9: 이미용/XEOHair_2024-2025_SeoulGyeonggi.xlsx
A10: 치킨 | B10: BHC | C10: 2025 | D10: 53080000 | E10: 636960000 | F10: 2224 | G10: 2026 | H10: 278640000 | I10: 원자료에 숫자로 표시된 항목만 합산; -/빈칸은 제외 | J10: 마이프차 연도별 정보; 원자료 단위 원/월 | K10: 치킨/BHC_창업정보.xlsx
A11: 치킨 | B11: 교촌치킨 | C11: 2025 | D11: 65640000 | E11: 787680000 | F11: 1362 | G11: 2025 | H11: 469580000 | I11: 원자료에 숫자로 표시된 항목만 합산; -/빈칸은 제외 | J11: 연도별 정보; 원자료 단위 원/월 | K11: 치킨/교촌치킨_창업정보.xlsx
A12: 치킨 | B12: 굽네치킨 | C12: 2024 | D12: 41550000 | E12: 498600000 | F12: 1252 | G12: 2026 | H12: 166540000 | I12: 원자료에 숫자로 표시된 항목만 합산; -/빈칸은 제외 | J12: 연도별 요청항목; 원자료 단위 원/월 | K12: 치킨/굽네치킨_창업정보.xlsx
A13: 치킨 | B13: 비비큐 | C13: 2024 | D13: 42390000 | E13: 508680000 | F13: 2155 | G13: 2026 | H13: 181560000 | I13: 원자료에 숫자로 표시된 항목만 합산; -/빈칸은 제외 | J13: 캡처 연도별 정보; 원자료 단위 원/월 | K13: 치킨/비비큐_창업정보.xlsx
A14: 치킨 | B14: 처갓집양념치킨 | C14: 2025 | D14: 28570000 | E14: 342840000 | F14: 1251 | G14: 2026 | H14: 58100000 | I14: 원자료에 숫자로 표시된 항목만 합산; -/빈칸은 제외 | J14: 매출 및 매장 수; 원자료 단위 원/월 | K14: 치킨/처갓집양념치킨_창업정보.xlsx
A15: 커피 | B15: 메가커피 | F15: 4016 | G15: 2025 | I15: 원자료에서 숫자형 창업비용 합계 미확인 | K15: 커피브랜드/1.메가커피/메가커피 정보공개서 2024년.xlsx
A16: 커피 | B16: 메가커피 | I16: 원자료에서 숫자형 창업비용 합계 미확인 | K16: 커피브랜드/1.메가커피/메가커피 정보공개서 2025.xlsx
A17: 커피 | B17: 컴포즈커피 | F17: 2649 | G17: 2024 | I17: 원자료에서 숫자형 창업비용 합계 미확인 | K17: 커피브랜드/2.컴포즈커피/컴포즈커피 정보공개서 2024년.xlsx
A18: 커피 | B18: 이디야커피 | F18: 2581 | G18: 2024 | I18: 원자료에서 숫자형 창업비용 합계 미확인 | K18: 커피브랜드/3.이디야커피/이디야커피 정보공개서 2024년.xlsx
A19: 커피 | B19: 빽다방 | F19: 1715 | G19: 2024 | I19: 원자료에서 숫자형 창업비용 합계 미확인 | K19: 커피브랜드/4.빽다방/빽다방 정보공개서 2024년.xlsx
A20: 커피 | B20: 투썸플레이스 | F20: 1670 | G20: 2024 | I20: 원자료에서 숫자형 창업비용 합계 미확인 | K20: 커피브랜드/5.투썸플레이스/Twosome_Place 정보공개서 2024년.xlsx
A21: 편의점 | B21: CU | F21: 18468 | G21: 2026 | H21: 48440000 | I21: 원자료에 숫자로 표시된 항목만 합산; -/빈칸은 제외 | K21: 편의점/CU_창업정보.xlsx
A22: 편의점 | B22: GS25 | F22: 18005 | G22: 2025 | H22: 45400000 | I22: 원자료에 숫자로 표시된 항목만 합산; -/빈칸은 제외 | K22: 편의점/GS25_창업정보.xlsx
A23: 편의점 | B23: 세븐일레븐 | C23: 2024 | D23: 42600000 | E23: 511200000 | F23: 7568 | G23: 2026 | H23: 148020000 | I23: 원자료에 숫자로 표시된 항목만 합산; -/빈칸은 제외 | J23: 매출 및 매장 수; 원자료 단위 원/월 | K23: 편의점/세븐일레븐_창업정보.xlsx
A24: 편의점 | B24: 이마트24 | C24: 2024 | D24: 37620000 | E24: 451440000 | F24: 5595 | G24: 2026 | H24: 148400000 | I24: 원자료에 숫자로 표시된 항목만 합산; -/빈칸은 제외 | J24: 매출 및 매장 수; 원자료 단위 원/월 | K24: 편의점/이마트24_창업정보.xlsx
